output/temporal_validation_2025_to_2026.csv
dataset,task,rows,accuracy,top2_accuracy,top3_accuracy,macro_f1,mean_probability_assigned_to_actual_pitch,mean_model_confidence,auc,brier,positive_rate,rmse,r2,target_mean
2025_holdout,next_pitch_dummy,52324,0.3192034248146166,,,,,,,,,,,
2025_holdout,next_pitch,52324,0.43377799862395844,0.6995833651861478,0.8562036541548811,0.28086712329046143,0.30772218801818985,0.42311686780996355,,,,,,
2025_holdout,whiff_or_weak,52324,0.7768519226358841,,,,,,0.7246993336578901,0.15519234124056147,0.2231671890528247,,,
2025_holdout,pitcher_run_value,52324,,,,,,,,,,0.2230813158829748,0.029232000605572406,0.0012248490176592004
2026_to_date,next_pitch,82282,0.39052283610024063,0.6433120245011059,0.8011715806616271,0.22613382139421503,0.28446476527480946,0.41778860465160866,,,,,,
2026_to_date,whiff_or_weak,82282,0.7782990204418949,,,,,,0.7199510469153071,0.15557076350509488,0.22243017914003063,,,
2026_to_date,pitcher_run_value,82275,,,,,,,,,,0.22261311343720813,0.027613734685311253,-0.00029255545426922045
